Workbook

Sheet 📦 진열 데이터
A1: 📦 진열 데이터 | 집기별 바코드 + 진열수량
A2: ← 수동 입력 | C2: ← 바코드 스캔 | D2: ← 직접 카운트
A3: 집기 ID | B3: 집기 종류 | C3: 바코드 (상품코드) | D3: 진열수량
A4: F001 | B4: FACE | C4: EEYWG24E0150165 | D4: 1
A5: F001 | B5: FACE | C5: EEYWG24E0142165 | D5: 1
A6: F001 | B6: FACE | C6: EEYWG24E0139170 | D6: 1
A7: F001 | B7: FACE | C7: EEYWG25E0159165 | D7: 1
A8: F001 | B8: FACE | C8: EEYWG25E0150165 | D8: 1
A9: F001 | B9: FACE | C9: EEYWG25E0125165 | D9: 1
A10: F001 | B10: FACE | C10: EEYWG24E0251160 | D10: 1
A11: F001 | B11: FACE | C11: EEYWG25E0139160 | D11: 1
A12: F002 | B12: FACE | C12: EEWHG25E0119160 | D12: 2
A13: F002 | B13: FACE | C13: EEVKG25B0299160 | D13: 2
A14: F002 | B14: FACE | C14: EEWHG24E0139170 | D14: 1
A15: F002 | B15: FACE | C15: EEYPG24E0101165 | D15: 2
... A459: M008 | B459: MQ | C459: EETCG24E0641155 | D459: 1

Sheet 💰 판매 실적
A1: 💰 판매 실적 | 회사 양식 그대로 복붙 또는 직접 입력
A2: ★ 款号(스타일번호) 가 진열 데이터의 바코드 앞 10자리와 자동 매칭됩니다
A3: 品类 | B3: 支社 | C3: 区域 | D3: 卖场 코드 | E3: 매장명 | F3: 卖场 유형 | G3: 매장유형 | H3: 款号 (스타일번호) | I3: 预定 단가 | J3: 决定 단가 | K3: 销售数量 ★판매수량 | L3: 销售额 ★매출(CNY)
A4: AB | B4: B331 | C4: 上海区域 | D4: CMCF | E4: EE 上海七宝万科广场 | F4: 02 | G4: 购物中心 | H4: EEABG23B01 | I4: 499 | J4: 499 | K4: =VLOOKUP(H4,'七宝0412-0511'!H:M,6,0) | L4: =VLOOKUP(H4,'七宝0412-0511'!H:O,8,0)
A5: AB | B5: B331 | C5: 上海区域 | D5: CMCF | E5: EE 上海七宝万科广场 | F5: 02 | G5: 购物中心 | H5: EEABG23B51 | I5: 199 | J5: 199 | K5: =VLOOKUP(H5,'七宝0412-0511'!H:M,6,0) | L5: =VLOOKUP(H5,'七宝0412-0511'!H:O,8,0)
A6: AC | B6: B331 | C6: 上海区域 | D6: CMCF | E6: EE 上海七宝万科广场 | F6: 02 | G6: 购物中心 | H6: EEACG23E01 | I6: 299 | J6: 299 | K6: =VLOOKUP(H6,'七宝0412-0511'!H:M,6,0) | L6: =VLOOKUP(H6,'七宝0412-0511'!H:O,8,0)
A7: AC | B7: B331 | C7: 上海区域 | D7: CMCF | E7: EE 上海七宝万科广场 | F7: 02 | G7: 购物中心 | H7: EEACG25D01 | I7: 399 | J7: 399 | K7: =VLOOKUP(H7,'七宝0412-0511'!H:M,6,0) | L7: =VLOOKUP(H7,'七宝0412-0511'!H:O,8,0)
A8: AK | B8: B331 | C8: 上海区域 | D8: CMCF | E8: EE 上海七宝万科广场 | F8: 02 | G8: 购物中心 | H8: EEAKG23B01 | I8: 999 | J8: 999 | K8: =VLOOKUP(H8,'七宝0412-0511'!H:M,6,0) | L8: =VLOOKUP(H8,'七宝0412-0511'!H:O,8,0)
A9: AK | B9: B331 | C9: 上海区域 | D9: CMCF | E9: EE 上海七宝万科广场 | F9: 02 | G9: 购物中心 | H9: EEAKG25B01 | I9: 1299 | J9: 1299 | K9: =VLOOKUP(H9,'七宝0412-0511'!H:M,6,0) | L9: =VLOOKUP(H9,'七宝0412-0511'!H:O,8,0)
A10: AK | B10: B331 | C10: 上海区域 | D10: CMCF | E10: EE 上海七宝万科广场 | F10: 02 | G10: 购物中心 | H10: EEAKG25E01 | I10: 1599 | J10: 1599 | K10: =VLOOKUP(H10,'七宝0412-0511'!H:M,6,0) | L10: =VLOOKUP(H10,'七宝0412-0511'!H:O,8,0)
A11: AS | B11: B331 | C11: 上海区域 | D11: CMCF | E11: EE 上海七宝万科广场 | F11: 02 | G11: 购物中心 | H11: EEASG23D01 | I11: 399 | J11: 399 | K11: =VLOOKUP(H11,'七宝0412-0511'!H:M,6,0) | L11: =VLOOKUP(H11,'七宝0412-0511'!H:O,8,0)
A12: AS | B12: B331 | C12: 上海区域 | D12: CMCF | E12: EE 上海七宝万科广场 | F12: 02 | G12: 购物中心 | H12: EEASG24Q1S | I12: 299 | J12: 299 | K12: =VLOOKUP(H12,'七宝0412-0511'!H:M,6,0) | L12: =VLOOKUP(H12,'七宝0412-0511'!H:O,8,0)
A13: BW | B13: B331 | C13: 上海区域 | D13: CMCF | E13: EE 上海七宝万科广场 | F13: 02 | G13: 购物中心 | H13: EEBWG23B01 | I13: 799 | J13: 799 | K13: =VLOOKUP(H13,'七宝0412-0511'!H:M,6,0) | L13: =VLOOKUP(H13,'七宝0412-0511'!H:O,8,0)
A14: CK | B14: B331 | C14: 上海区域 | D14: CMCF | E14: EE 上海七宝万科广场 | F14: 02 | G14: 购物中心 | H14: EECKG23B03 | I14: 799 | J14: 799 | K14: =VLOOKUP(H14,'七宝0412-0511'!H:M,6,0) | L14: =VLOOKUP(H14,'七宝0412-0511'!H:O,8,0)
A15: CK | B15: B331 | C15: 上海区域 | D15: CMCF | E15: EE 上海七宝万科广场 | F15: 02 | G15: 购物中心 | H15: EECKG23B04 | I15: 899 | J15: 899 | K15: =VLOOKUP(H15,'七宝0412-0511'!H:M,6,0) | L15: =VLOOKUP(H15,'七宝0412-0511'!H:O,8,0)
... A188: YW | B188: B331 | C188: 上海区域 | D188: CMCF | E188: EE 上海七宝万科广场 | F188: 02 | G188: 购物中心 | H188: EEYWG26B01 | I188: 899 | J188: 899 | K188: =VLOOKUP(H188,'七宝0412-0511'!H:M,6,0) | L188: =VLOOKUP(H188,'七宝0412-0511'!H:O,8,0)

Sheet 📋 작성 가이드
B1: VMD 데이터 입력 양식 — 작성 가이드
B3: 📦 진열 데이터 탭 — 4개 컬럼
B4: 컬럼 | C4: 입력 방식 | D4: 규칙 | E4: 예시
B5: 집기 ID | C5: 수동 | D5: F001~F016 / H001~H009 / T001~T003 / M001~M008 | E5: F001
B6: 집기 종류 | C6: 드롭다운 | D6: FACE / TABLE / HANGER / MQ | E6: FACE
B7: 바코드 | C7: 스캔 | D7: 15자리 EE로 시작, 공백 없이 | E7: EEYWG24E0150165
B8: 진열수량 | C8: 직접 카운트 | D8: 해당 집기에 진열된 실물 개수 | E8: 2
B10: 💰 판매 실적 탭 — 회사 양식
B11: 컬럼 | C11: 내용 | D11: 규칙 | E11: 예시
B12: 款号 ★ | C12: 스타일번호 (매칭 키) | D12: 바코드 앞 10자와 자동 매칭 | E12: EETJG24E01
B13: 销售数量 ★ | C13: 판매수량 | D13: 숫자만, 미판매=0 | E13: 7
B14: 销售额 ★ | C14: 매출 (CNY) | D14: 숫자만, 쉼표 없이 | E14: 3076
B15: 决定销售价 | C15: 결정단가 | D15: 단가는 여기서 자동 참조 | E15: 699
B16: 나머지 | C16: 회사 ERP 그대로 | D16: 복붙해도 됨 | E16: B331, CMCF…
B18: 🔗 두 탭 연결 구조
B19: 항목 | C19: 설명
B20: 매칭 키 | C20: 바코드 앞 10자리 = 款号
B21: 예시 | C21: EEYWG24E01|50|165 → EEYWG24E01
B22: 단가 참조 | C22: 款号 → 판매 실적 탭의 决定销售价 자동 참조
B23: 업데이트 주기 | C23: 진열탭 고정 / 판매탭 매주 교체

Sheet ✅ 유효값
A1: ✅ 유효값 & 매핑표 (수정 금지)
A3: 스타일코드(2자) → 카테고리 · 품목 매핑
A4: 스타일코드 | B4: 카테고리 | C4: 품목 | E4: 스타일코드 | F4: 카테고리 | G4: 품목
A5: AB | B5: 액세서리 ACC | C5: 皮带 | E5: OM | F5: 원피스 连衣裙 | G5: 连衣裙
A6: AC | B6: 액세서리 ACC | C6: ACC | E6: OW | F6: 원피스 连衣裙 | G6: 短袖连衣裙
A7: ACC | E7: RA | F7: 상의 上衣 | G7: 短袖T
A8: AG | B8: 액세서리 ACC | C8: ACC | E8: RN | F8: 상의 上衣 | G8: 背心
A9: AK | B9: 액세서리 ACC | C9: 包 | E9: RS | F9: 상의 上衣 | G9: 短袖T
A10: AM | B10: 액세서리 ACC | C10: ACC | E10: SK | F10: 상의 上衣 | G10: 针织衫
A11: AN | B11: 액세서리 ACC | C11: ACC | E11: TA | F11: 하의 下衣 | G11: 亚麻阔腿裤
A12: AP | B12: 액세서리 ACC | C12: 配饰 | E12: TC | F12: 하의 下衣 | G12: 长裤
A13: AS | B13: 액세서리 ACC | C13: 丝巾 | E13: TH | F13: 하의 下衣 | G13: 短裤
A14: AU | B14: 액세서리 ACC | C14: ACC | E14: TJ | F14: 하의 下衣 | G14: 牛仔裤
A15: AW | B15: 액세서리 ACC | C15: ACC | E15: TK | F15: 액세서리 ACC | G15: 帽子
A16: AY | B16: 액세서리 ACC | C16: ACC | E16: TM | F16: 하의 下衣 | G16: 面料裤
A17: BW | B17: 상의 上衣 | C17: 衬衫 | E17: VJ | F17: 상의 上衣 | G17: 牛仔
A18: CF | B18: 액세서리 ACC | C18: ACC | E18: VK | F18: 상의 上衣 | G18: 针织背心
A19: CK | B19: 상의 上衣 | C19: 针织开衫 | E19: VW | F19: 상의 上衣 | G19: 马甲
... A21: JA | B21: 상의 上衣 | C21: 轻薄夹克 | E21: WJ | F21: 하의 下衣 | G21: 牛仔半裙
A22: JD | E22: WM
A23: JH | B23: 상의 上衣 | C23: 牛仔外套 | E23: WR
A24: JJ | B24: 상의 上衣 | C24: 牛仔夹克 | E24: YA | F24: 상의 上衣 | G24: 短袖衬衫
A25: JK | B25: 상의 上衣 | C25: 西装夹克 | E25: YC | F25: 상의 上衣 | G25: 衬衫
A26: JL | B26: 상의 上衣 | C26: 牛仔外套 | E26: YJ | F26: 액세서리 ACC | G26: 牛仔ACC
A27: JP | B27: 상의 上衣 | C27: 羽绒服 | E27: YP | F27: 상의 上衣 | G27: 牛仔衬衫
A28: JT | B28: 상의 上衣 | C28: 牛仔外套 | E28: YS | F28: 상의 上衣 | G28: 条纹衬衫
A29: JW | B29: 상의 上衣 | E29: YW | F29: 상의 上衣 | G29: 亚麻衬衫
A30: KW | B30: 상의 上衣 | C30: 针织短袖 | E30: item
A31: LA | B31: 상의 上衣 | C31: 吊带 | E31: 内搭
A32: LS | B32: 액세서리 ACC | C32: 针织ACC | E32: 外套
A33: MT | B33: 상의 上衣 | E33: 廓形
A34: MZ | B34: 액세서리 ACC | C34: 针织配饰 | E34: 牛仔
A35: OJ | B35: 원피스 连衣裙 | C35: 牛仔连衣裙 | E35: 连衣裙
A36: OK | B36: 상의 上衣 | C36: 针织衫 | E36: 针织
A39: 컬러코드(2자리) → 컬러명 매핑
A40: 컬러코드 | B40: 컬러명 | E40: 컬러코드 | F40: 컬러명
A41: 01 | B41: (01)M/Indigo | E41: 49 | F41: (49)Khaki
A42: 15 | B42: (15)Grey | E42: 50 | F42: (50)Blue
A43: 16 | B43: (16)L/Grey | E43: 51 | F43: (51)L/Blue
A44: 17 | B44: (17)D/Grey | E44: 52 | F44: (52)D/Blue
...

Sheet 七宝0412-0511
B1: Table
M2: 销售数量 | N2: 卖场库存量 | O2: 销售额
A3: 品类 | B3: 支社 | D3: 卖场 | F3: 卖场类型 | H3: 款号 | I3: 预定销售价 | J3: 决定销售价 | K3: 入库要求日期 | L3: 卖场状态 | M3: PCS | N3: PCS | O3: CNY
A4: =MID(H4,3,2) | B4: B331 | C4: 上海区域 | D4: CMCF | E4: EE 上海七宝万科广场 | F4: 02 | G4: 购物中心 | H4: EEABG23B01 | I4: 499 | J4: 499 | K4: 46045 | L4: 营业中 | N4: 2 | R4: 款号 | S4: 销售额 | T4: 销售量
A5: =MID(H5,3,2) | B5: B331 | C5: 上海区域 | D5: CMCF | E5: EE 上海七宝万科广场 | F5: 02 | G5: 购物中心 | H5: EEABG23B51 | I5: 199 | J5: 199 | K5: 46106 | L5: 营业中 | N5: 2 | R5: EETJG24E01 | S5: =SUMIFS(O:O,H:H,R5) | T5: =SUMIFS(M:M,H:H,R5)
A6: =MID(H6,3,2) | B6: B331 | C6: 上海区域 | D6: CMCF | E6: EE 上海七宝万科广场 | F6: 02 | G6: 购物中心 | H6: EEACG23E01 | I6: 299 | J6: 299 | K6: 46038 | L6: 营业中 | N6: 12 | R6: EETAG24E02 | S6: =SUMIFS(O:O,H:H,R6) | T6: =SUMIFS(M:M,H:H,R6)
A7: =MID(H7,3,2) | B7: B331 | C7: 上海区域 | D7: CMCF | E7: EE 上海七宝万科广场 | F7: 02 | G7: 购物中心 | H7: EEACG25D01 | I7: 399 | J7: 399 | K7: 46106 | L7: 营业中 | M7: 0 | N7: 2 | O7: 0 | R7: EETCG24E06 | S7: =SUMIFS(O:O,H:H,R7) | T7: =SUMIFS(M:M,H:H,R7)
A8: =MID(H8,3,2) | B8: B331 | C8: 上海区域 | D8: CMCF | E8: EE 上海七宝万科广场 | F8: 02 | G8: 购物中心 | H8: EEAKG23B01 | I8: 999 | J8: 999 | K8: 46059 | L8: 营业中 | N8: 1 | R8: EETJG23E04 | S8: =SUMIFS(O:O,H:H,R8) | T8: =SUMIFS(M:M,H:H,R8)
A9: =MID(H9,3,2) | B9: B331 | C9: 上海区域 | D9: CMCF | E9: EE 上海七宝万科广场 | F9: 02 | G9: 购物中心 | H9: EEAKG25B01 | I9: 1299 | J9: 1299 | K9: 46112 | L9: 营业中 | N9: 2 | R9: EETAG24B03 | S9: =SUMIFS(O:O,H:H,R9) | T9: =SUMIFS(M:M,H:H,R9)
A10: =MID(H10,3,2) | B10: B331 | C10: 上海区域 | D10: CMCF | E10: EE 上海七宝万科广场 | F10: 02 | G10: 购物中心 | H10: EEAKG25E01 | I10: 1599 | J10: 1599 | K10: 46112 | L10: 营业中 | N10: 2 | R10: EETJG23E06 | S10: =SUMIFS(O:O,H:H,R10) | T10: =SUMIFS(M:M,H:H,R10)
A11: =MID(H11,3,2) | B11: B331 | C11: 上海区域 | D11: CMCF | E11: EE 上海七宝万科广场 | F11: 02 | G11: 购物中心 | H11: EEASG23D01 | I11: 399 | J11: 399 | K11: 46045 | L11: 营业中 | N11: 2 | R11: EETCG24E01 | S11: =SUMIFS(O:O,H:H,R11) | T11: =SUMIFS(M:M,H:H,R11)
A12: =MID(H12,3,2) | B12: B331 | C12: 上海区域 | D12: CMCF | E12: EE 上海七宝万科广场 | F12: 02 | G12: 购物中心 | H12: EEASG24Q1S | I12: 299 | J12: 299 | K12: 46119 | L12: 营业中 | N12: 2 | R12: EETJG24E05 | S12: =SUMIFS(O:O,H:H,R12) | T12: =SUMIFS(M:M,H:H,R12)
A13: =MID(H13,3,2) | B13: B331 | C13: 上海区域 | D13: CMCF | E13: EE 上海七宝万科广场 | F13: 02 | G13: 购物中心 | H13: EEBWG23B01 | I13: 799 | J13: 799 | K13: 46027 | L13: 营业中 | M13: 1 | N13: 0 | O13: 503 | R13: EETJG25B03 | S13: =SUMIFS(O:O,H:H,R13) | T13: =SUMIFS(M:M,H:H,R13)
A14: =MID(H14,3,2) | B14: B331 | C14: 上海区域 | D14: CMCF | E14: EE 上海七宝万科广场 | F14: 02 | G14: 购物中心 | H14: EECKG23B03 | I14: 899 | J14: 799 | K14: 46048 | L14: 营业中 | N14: 0 | R14: EETJG23E01 | S14: =SUMIFS(O:O,H:H,R14) | T14: =SUMIFS(M:M,H:H,R14)
A15: =MID(H15,3,2) | B15: B331 | C15: 上海区域 | D15: CMCF | E15: EE 上海七宝万科广场 | F15: 02 | G15: 购物中心 | H15: EECKG23B04 | I15: 899 | J15: 899 | K15: 46048 | L15: 营业中 | N15: 0 | R15: EETAG24E04 | S15: =SUMIFS(O:O,H:H,R15) | T15: =SUMIFS(M:M,H:H,R15)
A16: =MID(H16,3,2) | B16: B331 | C16: 上海区域 | D16: CMCF | E16: EE 上海七宝万科广场 | F16: 02 | G16: 购物中心 | H16: EEJAG23E01 | I16: 1299 | J16: 1299 | K16: 46048 | L16: 营业中 | M16: 2 | N16: 0 | O16: 1299 | R16: EETHG25E04 | S16: =SUMIFS(O:O,H:H,R16) | T16: =SUMIFS(M:M,H:H,R16)
A17: =MID(H17,3,2) | B17: B331 | C17: 上海区域 | D17: CMCF | E17: EE 上海七宝万科广场 | F17: 02 | G17: 购物中心 | H17: EEJAG24B04 | I17: 1999 | J17: 1599 | K17: 46125 | L17: 营业中 | M17: 2 | N17: 1 | O17: 1839
A18: =MID(H18,3,2) | B18: B331 | C18: 上海区域 | D18: CMCF | E18: EE 上海七宝万科广场 | F18: 02 | G18: 购物中心 | H18: EECKG23R31 | I18: 999 | J18: 999 | K18: 46052 | L18: 营业中 | M18: 0 | N18: 0 | O18: 0 | R18: EETHG24E02 | S18: =SUMIFS(O:O,H:H,R18) | T18: =SUMIFS(M:M,H:H,R18)
A19: =MID(H19,3,2) | B19: B331 | C19: 上海区域 | D19: CMCF | E19: EE 上海七宝万科广场 | F19: 02 | G19: 购物中心 | H19: EECKG23R33 | I19: 899 | J19: 899 | K19: 46045 | L19: 营业中 | N19: 0 | R19: EETJG24E06 | S19: =SUMIFS(O:O,H:H,R19) | T19: =SUMIFS(M:M,H:H,R19)
A20: =MID(H20,3,2) | B20: B331 | C20: 上海区域 | D20: CMCF | E20: EE 上海七宝万科广场 | F20: 02 | G20: 购物中心 | H20: EEJJG23D03 | I20: 1599 | J20: 1599 | K20: 46063 | L20: 营业中 | M20: 1 | N20: 0 | O20: 480
A21: =MID(H21,3,2) | B21: B331 | C21: 上海区域 | D21: CMCF | E21: EE 上海七宝万科广场 | F21: 02 | G21: 购物中心 | H21: EECKG25B04 | I21: 899 | J21: 599 | K21: 46127 | L21: 营业中 | N21: 5 | R21: EETJG23B1G | S21: =SUMIFS(O:O,H:H,R21) | T21: =SUMIFS(M:M,H:H,R21)
A22: =MID(H22,3,2) | B22: B331 | C22: 上海区域 | D22: CMCF | E22: EE 上海七宝万科广场 | F22: 02 | G22: 购物中心 | H22: EEKWG23D02 | I22: 699 | J22: 699 | K22: 46048 | L22: 营业中 | M22: 1 | N22: 0 | O22: 489
A23: =MID(H23,3,2) | B23: B331 | C23: 上海区域 | D23: CMCF | E23: EE 上海七宝万科广场 | F23: 02 | G23: 购物中心 | H23: EELAG23E01 | I23: 799 | J23: 699 | K23: 46048 | L23: 营业中 | M23: 2 | N23: 0 | O23: 681
A24: =MID(H24,3,2) | B24: B331 | C24: 上海区域 | D24: CMCF | E24: EE 上海七宝万科广场 | F24: 02 | G24: 购物中心 | H24: EEHWG25B01 | I24: 599 | J24: 499 | K24: 46129 | L24: 营业中 | N24: 2 | R24: EETJG24E04 | S24: =SUMIFS(O:O,H:H,R24) | T24: =SUMIFS(M:M,H:H,R24)
A25: =MID(H25,3,2) | B25: B331 | C25: 上海区域 | D25: CMCF | E25: EE 上海七宝万科广场 | F25: 02 | G25: 购物中心 | H25: EEJAG23B03 | I25: 1599 | J25: 1599 | K25: 46048 | L25: 营业中 | N25: 0 | R25: EETMG25B51 | S25: =SUMIFS(O:O,H:H,R25) | T25: =SUMIFS(M:M,H:H,R25)
A26: =MID(H26,3,2) | B26: B331 | C26: 上海区域 | D26: CMCF | E26: EE 上海七宝万科广场 | F26: 02 | G26: 购物中心 | H26: EEJAG23B04 | I26: 1599 | J26: 1599 | K26: 46048 | L26: 营业中 | N26: 0 | R26: EETCG23E01 | S26: =SUMIFS(O:O,H:H,R26) | T26: =SUMIFS(M:M,H:H,R26)
A27: =MID(H27,3,2) | B27: B331 | C27: 上海区域 | D27: CMCF | E27: EE 上海七宝万科广场 | F27: 02 | G27: 购物中心 | H27: EEJAG23B51 | I27: 1599 | J27: 1599 | K27: 46062 | L27: 营业中 | N27: 0 | R27: EETHG24E03 | S27: =SUMIFS(O:O,H:H,R27) | T27: =SUMIFS(M:M,H:H,R27)
A28: =MID(H28,3,2) | B28: B331 | C28: 上海区域 | D28: CMCF | E28: EE 上海七宝万科广场 | F28: 02 | G28: 购物中心 | H28: EERAG25B1G | I28: 499 | J28: 499 | K28: 46106 | L28: 营业中 | M28: 2 | N28: 0 | O28: 299
A29: =MID(H29,3,2) | B29: B331 | C29: 上海区域 | D29: CMCF | E29: EE 上海七宝万科广场 | F29: 02 | G29: 购物中心 | H29: EEJAG23E02 | I29: 1299 | J29: 1599 | K29: 46048 | L29: 营业中 | N29: 0 | R29: EETJG23B05 | S29: =SUMIFS(O:O,H:H,R29) | T29: =SUMIFS(M:M,H:H,R29)
A30: =MID(H30,3,2) | B30: B331 | C30: 上海区域 | D30: CMCF | E30: EE 上海七宝万科广场 | F30: 02 | G30: 购物中心 | H30: EEJAG23R01 | I30: 1999 | J30: 1999 | K30: 46120 | L30: 营业中 | N30: 0 | R30: EETJG24B57 | S30: =SUMIFS(O:O,H:H,R30) | T30: =SUMIFS(M:M,H:H,R30)
A31: =MID(H31,3,2) | B31: B331 | C31: 上海区域 | D31: CMCF | E31: EE 上海七宝万科广场 | F31: 02 | G31: 购物中心 | H31: EEJAG24B01 | I31: 1599 | J31: 1599 | K31: 46078 | L31: 营业中 | N31: 0 | R31: EETJG24B58 | S31: =SUMIFS(O:O,H:H,R31) | T31: =SUMIFS(M:M,H:H,R31)
A32: =MID(H32,3,2) | B32: B331 | C32: 上海区域 | D32: CMCF | E32: EE 上海七宝万科广场 | F32: 02 | G32: 购物中心 | H32: EEJAG24B02 | I32: 1599 | J32: 1599 | K32: 46078 | L32: 营业中 | N32: 4 | R32: EETKG25D01 | S32: =SUMIFS(O:O,H:H,R32) | T32: =SUMIFS(M:M,H:H,R32)
A33: =MID(H33,3,2) | B33: B331 | C33: 上海区域 | D33: CMCF | E33: EE 上海七宝万科广场 | F33: 02 | G33: 购物中心 | H33: EERAG25E1G | I33: 399 | J33: 399 | K33: 46106 | L33: 营业中 | M33: 1 | N33: 0 | O33: 120
A34: =MID(H34,3,2) | B34: B331 | C34: 上海区域 | D34: CMCF | E34: EE 上海七宝万科广场 | F34: 02 | G34: 购物中心 | H34: EERSG24B01 | I34: 399 | J34: 399 | K34: 46106 | L34: 营业中 | M34: 1 | N34: 0 | O34: 279
A35: =MID(H35,3,2) | B35: B331 | C35: 上海区域 | D35: CMCF | E35: EE 上海七宝万科广场 | F35: 02 | G35: 购物中心 | H35: EEJDG23R31 | I35: 1599 | J35: 1599 | K35: 46058 | L35: 营业中 | N35: 0
A36: =MID(H36,3,2) | B36: B331 | C36: 上海区域 | D36: CMCF | E36: EE 上海七宝万科广场 | F36: 02 | G36: 购物中心 | H36: EEJJG23B01 | I36: 899 | J36: 899 | K36: 46044 | L36: 营业中 | M36: 0 | N36: 0 | O36: 0
A37: =MID(H37,3,2) | B37: B331 | C37: 上海区域 | D37: CMCF | E37: EE 上海七宝万科广场 | F37: 02 | G37: 购物中心 | H37: EETCG23E02 | I37: 899 | J37: 999 | K37: 46085 | L37: 营业中 | M37: 1 | N37: 5 | O37: 300
A38: =MID(H38,3,2) | B38: B331 | C38: 上海区域 | D38: CMCF | E38: EE 上海七宝万科广场 | F38: 02 | G38: 购物中心 | H38: EEWHG23B02 | I38: 899 | J38: 999 | K38: 46045 | L38: 营业中 | M38: 1 | N38: 0 | O38: 300
A39: =MID(H39,3,2) | B39: B331 | C39: 上海区域 | D39: CMCF | E39: EE 上海七宝万科广场 | F39: 02 | G39: 购物中心 | H39: EEJLG23B51 | I39: 1599 | J39: 1599 | K39: 46099 | L39: 营业中 | N39: 0
A40: =MID(H40,3,2) | B40: B331 | C40: 上海区域 | D40: CMCF | E40: EE 上海七宝万科广场 | F40: 02 | G40: 购物中心 | H40: EEJWG23R31 | I40: 3999 | J40: 3999 | K40: 46052 | L40: 营业中 | N40: 0
...
